Workbook

Sheet External_Auto (v3)
A1: Market | B1: DMA | C1: CBM | D1: Description | E1: NextGen_TAZ | F1: Count2018 | G1: share | H1: Count2022
A2: Auto | B2: 3 | C2: 0 | D2: I-95 | E2: 11560 | F2: 63116 | G2: 0.47394347 | H2: =38266*2 -> 76532
A3: Auto | B3: 2 | C3: 0 | D3: I-75 | E3: 11548 | F3: 41556 | G3: 0.31204758
A4: Auto | B4: 1 | C4: 0 | D4: I-10 | E4: 11504 | F4: 28500 | G4: 0.21400895
A5: Auto | B5: 1 | C5: 1 | D5: US 90 | E5: 11503 | F5: 5059 | G5: 0.10296123
A6: Auto | B6: 1 | C6: 1 | D6: SR 89 | E6: 11510 | F6: 1200 | G6: 0.024422509
A7: Auto | B7: 1 | C7: 1 | D7: SR 189 | E7: 11513 | F7: 2700 | G7: 0.054950646
A8: Auto | B8: 1 | C8: 1 | D8: SR 87 | E8: 11513 | F8: 2700 | G8: 0.054950646
A9: Auto | B9: 1 | C9: 1 | D9: CR 185 | E9: 11520 | F9: 1600 | G9: 0.032563346
A10: Auto | B10: 1 | C10: 1 | D10: SR 77 | E10: 11527 | F10: 3217 | G10: 0.065472677
A11: Auto | B11: 1 | C11: 1 | D11: SR 71 | E11: 11531 | F11: 1950 | G11: 0.039686578
A12: Auto | B12: 1 | C12: 1 | D12: SR 2 | E12: 11533 | F12: 2015 | G12: 0.041009464
A13: Auto | B13: 1 | C13: 1 | D13: US 29 | E13: 11509 | F13: 11900 | G13: 0.24218989
A14: Auto | B14: 1 | C14: 1 | D14: US 331/SR 85 | E14: 11516 | F14: 4017 | G14: 0.08175435
... A26: Auto | B26: 2 | C26: 2 | D26: US 19 | E26: 11542 | F26: 3800 | G26: 0.1208075
A27: Auto | B27: 3 | C27: 3 | D27: SR 2 | E27: 11556 | F27: 3100 | G27: 0.17398137 | H27: =(1484)*2 -> 2968
A28: Auto | B28: 3 | C28: 3 | D28: SR 79 | E28: 11557 | F28: 3100 | G28: 0.17398137 | H28: =1750*2 -> 3500
A29: Auto | B29: 3 | C29: 3 | D29: US 17 | E29: 11559 | F29: 2900 | G29: 0.16275676 | H29: =2150*2 -> 4300
A30: Auto | B30: 3 | C30: 3 | D30: US 1 | E30: 11558 | F30: 8718 | G30: 0.4892805 | H30: =4940*2 -> 9880
A31: Auto | B31: 3 | C31: 3 | D31: SR 2 | E31: 11555 | H31: =200*2 -> 400

Sheet External_Auto (v4)
A1: Market | B1: DMA | C1: CBM | D1: Description | E1: NextGen_TAZ | F1: Count2022 | G1: share | H1: Count2022
A2: Auto | B2: 1 | C2: 0 | D2: I-10 | E2: 11504 | F2: 36000 | G2: 0.22294335 | H2: =18000*2 -> 36000 | I2: =H2/J$2 -> 0.22294335 | J2: =SUM(H2:H4) -> 161476 | K2: =ROUND(SUM(J:J),-3) -> 346000
A3: Auto | B3: 2 | C3: 0 | D3: I-75 | E3: 11548 | F3: 48944 | G3: 0.30310387 | H3: =24472*2 -> 48944 | I3: =H3/J$2 -> 0.30310387
A4: Auto | B4: 3 | C4: 0 | D4: I-95 | E4: 11560 | F4: 76532 | G4: 0.47395279 | H4: =38266*2 -> 76532 | I4: =H4/J$2 -> 0.47395279
A5: Auto | B5: 1 | C5: 1 | D5: SR 2 | E5: 11533 | F5: 2394 | G5: 0.020188391 | H5: =1197*2 -> 2394 | I5: =H5/J$5 -> 0.020188391 | J5: =SUM(H5:H35) -> 118583
A6: Auto | B6: 1 | C6: 1 | E6: 11532 | F6: 850 | G6: 0.0071679752 | H6: =850 -> 850 | I6: =H6/J$5 -> 0.0071679752
A7: Auto | B7: 1 | C7: 1 | D7: SR 71 | E7: 11531 | F7: 1750 | G7: 0.014757596 | H7: =875*2 -> 1750 | I7: =H7/J$5 -> 0.014757596
A8: Auto | B8: 1 | C8: 1 | E8: 11530 | F8: 600 | G8: 0.0050597472 | H8: 600 | I8: =H8/J$5 -> 0.0050597472
A9: Auto | B9: 1 | C9: 1 | D9: US 231/SR 75 | E9: 11529 | F9: 15628 | G9: 0.13178955 | H9: =7814*2 -> 15628 | I9: =H9/J$5 -> 0.13178955
A10: Auto | B10: 1 | C10: 1 | D10: SR 77 | E10: 11527 | F10: 2964 | G10: 0.024995151 | H10: =1482*2 -> 2964 | I10: =H10/J$5 -> 0.024995151
A11: Auto | B11: 1 | C11: 1 | D11: CR 171 + CR 173 (split 1450) | E11: 11526 | F11: 1600 | G11: 0.013492659 | H11: 1600 | I11: =H11/J$5 -> 0.013492659
A12: Auto | B12: 1 | C12: 1 | D12: FL 79 + CR 173 (split 1450) | E12: 11525 | F12: 4100 | G12: 0.034574939 | H12: 4100 | I12: =H12/J$5 -> 0.034574939
A13: Auto | B13: 1 | C13: 1 | E13: 11524 | F13: 500 | G13: 0.004216456 | H13: 500 | I13: =H13/J$5 -> 0.004216456
A14: Auto | B14: 1 | C14: 1 | E14: 11523 | F14: 600 | G14: 0.0050597472 | H14: 600 | I14: =H14/J$5 -> 0.0050597472
A15: Auto | B15: 1 | C15: 1 | E15: 11522 | F15: 700 | G15: 0.0059030384 | H15: 700 | I15: =H15/J$5 -> 0.0059030384
A16: Auto | B16: 1 | C16: 1 | E16: 11521 | F16: 600 | G16: 0.0050597472 | H16: 600 | I16: =H16/J$5 -> 0.0050597472
A17: Auto | B17: 1 | C17: 1 | D17: CR 185 | E17: 11520 | F17: 1700 | G17: 0.01433595 | H17: 1700 | I17: =H17/J$5 -> 0.01433595
A18: Auto | B18: 1 | C18: 1 | E18: 11519 | F18: 1600 | G18: 0.013492659 | H18: 1600 | I18: =H18/J$5 -> 0.013492659
A19: Auto | B19: 1 | C19: 1 | E19: 11518 | F19: 2500 | G19: 0.02108228 | H19: 2500 | I19: =H19/J$5 -> 0.02108228
A20: Auto | B20: 1 | C20: 1 | E20: 11517 | F20: 525 | G20: 0.0044272788 | H20: 525 | I20: =H20/J$5 -> 0.0044272788
A21: Auto | B21: 1 | C21: 1 | D21: US 331/SR 85 | E21: 11516 | F21: 5160 | G21: 0.043513826 | H21: =2580*2 -> 5160 | I21: =H21/J$5 -> 0.043513826
A22: Auto | B22: 1 | C22: 1 | E22: 11515 | F22: 2800 | G22: 0.023612154 | H22: 2800 | I22: =H22/J$5 -> 0.023612154
A23: Auto | B23: 1 | C23: 1 | E23: 11514 | F23: 4800 | G23: 0.040477977 | H23: 4800 | I23: =H23/J$5 -> 0.040477977
A24: Auto | B24: 1 | C24: 1 | D24: SR 189 | E24: 11513 | F24: 3300 | G24: 0.027828609 | H24: =1650*2 -> 3300 | I24: =H24/J$5 -> 0.027828609
A25: Auto | B25: 1 | C25: 1 | E25: 11512 | F25: 400 | G25: 0.0033731648 | H25: 400 | I25: =H25/J$5 -> 0.0033731648
A26: Auto | B26: 1 | C26: 1 | E26: 11511 | F26: 3000 | G26: 0.025298736 | H26: 3000 | I26: =H26/J$5 -> 0.025298736
A27: Auto | B27: 1 | C27: 1 | D27: SR 89 | E27: 11510 | F27: 1100 | G27: 0.0092762032 | H27: 1100 | I27: =H27/J$5 -> 0.0092762032
A28: Auto | B28: 1 | C28: 1 | D28: US 29 | E28: 11509 | F28: 1500 | G28: 0.012649368 | H28: =750*2 -> 1500 | I28: =H28/J$5 -> 0.012649368
A29: Auto | B29: 1 | C29: 1 | D29: US 29 | E29: 11508 | F29: 12300 | G29: 0.10372482 | H29: =6150*2 -> 12300 | I29: =H29/J$5 -> 0.10372482
A30: Auto | B30: 1 | C30: 1 | E30: 11507 | F30: 5852 | G30: 0.049349401 | H30: =2926*2 -> 5852 | I30: =H30/J$5 -> 0.049349401
A31: Auto | B31: 1 | C31: 1 | E31: 11506 | F31: 250 | G31: 0.002108228 | H31: 250 | I31: =H31/J$5 -> 0.002108228
A32: Auto | B32: 1 | C32: 1 | E32: 11505 | F32: 4400 | G32: 0.037104813 | H32: 4400 | I32: =H32/J$5 -> 0.037104813
A33: Auto | B33: 1 | C33: 1 | D33: US 90 | E33: 11503 | F33: 6594 | G33: 0.055606622 | H33: =3297*2 -> 6594 | I33: =H33/J$5 -> 0.055606622
A34: Auto | B34: 1 | C34: 1 | D34: US 98 | E34: 11502 | F34: 14516 | G34: 0.12241215 | H34: =7258*2 -> 14516 | I34: =H34/J$5 -> 0.12241215
A35: Auto | B35: 1 | C35: 1 | D35: AL 182 | E35: 11501 | F35: 14000 | G35: 0.11806077 | H35: =7000*2 -> 14000 | I35: =H35/J$5 -> 0.11806077
A36: Auto | B36: 2 | C36: 2 | E36: 11554 | F36: 400 | G36: 0.0088526912 | H36: =200*2 -> 400 | I36: =H36/J$36 -> 0.0088526912 | J36: =SUM(H36:H56) -> 45184
A37: Auto | B37: 2 | C37: 2 | D37: US 441 | E37: 11553 | F37: 950 | G37: 0.021025142 | H37: =475*2 -> 950 | I37: =H37/J$36 -> 0.021025142
A38: Auto | B38: 2 | C38: 2 | E38: 11552 | F38: 1200 | G38: 0.026558074 | H38: =1200 -> 1200 | I38: =H38/J$36 -> 0.026558074
A39: Auto | B39: 2 | C39: 2 | E39: 11551 | F39: 1000 | G39: 0.022131728 | H39: 1000 | I39: =H39/J$36 -> 0.022131728
A40: Auto | B40: 2 | C40: 2 | D40: US 41 (split 1300) | E40: 11550 | F40: 1400 | G40: 0.030984419 | H40: 1400 | I40: =H40/J$36 -> 0.030984419
...

Sheet External_Auto
A1: Market | B1: DMA | C1: CBM | D1: Description | E1: NextGen_TAZ | F1: Count2023 | G1: share | H1: Count2023
A2: Auto | B2: 1 | C2: 0 | D2: I-10 | E2: 11504 | F2: 36000 | G2: 0.22543678 | H2: =VLOOKUP(E2,Link_TAZ_lookup!H:I,2,FALSE) -> 36000 | I2: =H2/J$2 -> 0.22543678 | J2: =SUM(H2:H4) -> 159690 | K2: =ROUND(SUM(J:J),-3) -> 285000
A3: Auto | B3: 2 | C3: 0 | D3: I-75 | E3: 11548 | F3: 48054 | G3: 0.30092053 | H3: =VLOOKUP(E3,Link_TAZ_lookup!H:I,2,FALSE) -> 48054 | I3: =H3/J$2 -> 0.30092053
A4: Auto | B4: 3 | C4: 0 | D4: I-95 | E4: 11560 | F4: 75636 | G4: 0.47364268 | H4: =VLOOKUP(E4,Link_TAZ_lookup!H:I,2,FALSE) -> 75636 | I4: =H4/J$2 -> 0.47364268
A5: Auto | B5: 1 | C5: 1 | D5: SR 2 | E5: 11533 | F5: 550 | G5: 0.0075465485 | H5: =VLOOKUP(E5,Link_TAZ_lookup!H:I,2,FALSE) -> 550 | I5: =H5/J$5 -> 0.0075465485 | J5: =SUM(H5:H35) -> 72881
A6: Auto | B6: 1 | C6: 1 | E6: 11532 | F6: 500 | G6: 0.0068604986 | H6: =VLOOKUP(E6,Link_TAZ_lookup!H:I,2,FALSE) -> 500 | I6: =H6/J$5 -> 0.0068604986
A7: Auto | B7: 1 | C7: 1 | D7: SR 71 | E7: 11531 | F7: 1050 | G7: 0.014407047 | H7: =VLOOKUP(E7,Link_TAZ_lookup!H:I,2,FALSE) -> 1050 | I7: =H7/J$5 -> 0.014407047
A8: Auto | B8: 1 | C8: 1 | E8: 11530 | F8: 375 | G8: 0.005145374 | H8: =VLOOKUP(E8,Link_TAZ_lookup!H:I,2,FALSE) -> 375 | I8: =H8/J$5 -> 0.005145374
A9: Auto | B9: 1 | C9: 1 | D9: US 231/SR 75 | E9: 11529 | F9: 15876 | G9: 0.21783455 | H9: =VLOOKUP(E9,Link_TAZ_lookup!H:I,2,FALSE) -> 15876 | I9: =H9/J$5 -> 0.21783455
A10: Auto | B10: 1 | C10: 1 | D10: SR 77 | E10: 11527 | F10: 1476 | G10: 0.020252192 | H10: =VLOOKUP(E10,Link_TAZ_lookup!H:I,2,FALSE) -> 1476 | I10: =H10/J$5 -> 0.020252192
A11: Auto | B11: 1 | C11: 1 | D11: CR 171 + CR 173 (split 1450) | E11: 11526 | F11: 800 | G11: 0.010976798 | H11: =VLOOKUP(E11,Link_TAZ_lookup!H:I,2,FALSE) -> 800 | I11: =H11/J$5 -> 0.010976798
A12: Auto | B12: 1 | C12: 1 | D12: FL 79 + CR 173 (split 1450) | E12: 11525 | F12: 2050 | G12: 0.028128044 | H12: =VLOOKUP(E12,Link_TAZ_lookup!H:I,2,FALSE) -> 2050 | I12: =H12/J$5 -> 0.028128044
A13: Auto | B13: 1 | C13: 1 | E13: 11524 | F13: 275 | G13: 0.0037732742 | H13: =VLOOKUP(E13,Link_TAZ_lookup!H:I,2,FALSE) -> 275 | I13: =H13/J$5 -> 0.0037732742
A14: Auto | B14: 1 | C14: 1 | E14: 11523 | F14: 350 | G14: 0.004802349 | H14: =VLOOKUP(E14,Link_TAZ_lookup!H:I,2,FALSE) -> 350 | I14: =H14/J$5 -> 0.004802349
A15: Auto | B15: 1 | C15: 1 | E15: 11522 | F15: 275 | G15: 0.0037732742 | H15: =VLOOKUP(E15,Link_TAZ_lookup!H:I,2,FALSE) -> 275 | I15: =H15/J$5 -> 0.0037732742
A16: Auto | B16: 1 | C16: 1 | E16: 11521 | F16: 475 | G16: 0.0065174737 | H16: =VLOOKUP(E16,Link_TAZ_lookup!H:I,2,FALSE) -> 475 | I16: =H16/J$5 -> 0.0065174737
A17: Auto | B17: 1 | C17: 1 | D17: CR 185 | E17: 11520 | F17: 850 | G17: 0.011662848 | H17: =VLOOKUP(E17,Link_TAZ_lookup!H:I,2,FALSE) -> 850 | I17: =H17/J$5 -> 0.011662848
A18: Auto | B18: 1 | C18: 1 | E18: 11519 | F18: 800 | G18: 0.010976798 | H18: =VLOOKUP(E18,Link_TAZ_lookup!H:I,2,FALSE) -> 800 | I18: =H18/J$5 -> 0.010976798
A19: Auto | B19: 1 | C19: 1 | E19: 11518 | F19: 1300 | G19: 0.017837296 | H19: =VLOOKUP(E19,Link_TAZ_lookup!H:I,2,FALSE) -> 1300 | I19: =H19/J$5 -> 0.017837296
A20: Auto | B20: 1 | C20: 1 | E20: 11517 | F20: 2000 | G20: 0.027441994 | H20: =VLOOKUP(E20,Link_TAZ_lookup!H:I,2,FALSE) -> 2000 | I20: =H20/J$5 -> 0.027441994
A21: Auto | B21: 1 | C21: 1 | D21: US 331/SR 85 | E21: 11516 | F21: 2557 | G21: 0.03508459 | H21: =VLOOKUP(E21,Link_TAZ_lookup!H:I,2,FALSE) -> 2557 | I21: =H21/J$5 -> 0.03508459
A22: Auto | B22: 1 | C22: 1 | E22: 11515 | F22: 1450 | G22: 0.019895446 | H22: =VLOOKUP(E22,Link_TAZ_lookup!H:I,2,FALSE) -> 1450 | I22: =H22/J$5 -> 0.019895446
A23: Auto | B23: 1 | C23: 1 | E23: 11514 | F23: 2000 | G23: 0.027441994 | H23: =VLOOKUP(E23,Link_TAZ_lookup!H:I,2,FALSE) -> 2000 | I23: =H23/J$5 -> 0.027441994
A24: Auto | B24: 1 | C24: 1 | D24: SR 189 | E24: 11513 | F24: 2000 | G24: 0.027441994 | H24: =VLOOKUP(E24,Link_TAZ_lookup!H:I,2,FALSE) -> 2000 | I24: =H24/J$5 -> 0.027441994
A25: Auto | B25: 1 | C25: 1 | E25: 11512 | F25: 2025 | G25: 0.027785019 | H25: =VLOOKUP(E25,Link_TAZ_lookup!H:I,2,FALSE) -> 2025 | I25: =H25/J$5 -> 0.027785019
A26: Auto | B26: 1 | C26: 1 | E26: 11511 | F26: 3000 | G26: 0.041162992 | H26: 3000 | I26: =H26/J$5 -> 0.041162992
A27: Auto | B27: 1 | C27: 1 | D27: SR 89 | E27: 11510 | F27: 575 | G27: 0.0078895734 | H27: =VLOOKUP(E27,Link_TAZ_lookup!H:I,2,FALSE) -> 575 | I27: =H27/J$5 -> 0.0078895734
A28: Auto | B28: 1 | C28: 1 | D28: US 29 | E28: 11509 | F28: 5750 | G28: 0.078895734 | H28: =VLOOKUP(E28,Link_TAZ_lookup!H:I,2,FALSE) -> 5750 | I28: =H28/J$5 -> 0.078895734
A29: Auto | B29: 1 | C29: 1 | D29: US 29 | E29: 11508 | F29: 800 | G29: 0.010976798 | H29: =VLOOKUP(E29,Link_TAZ_lookup!H:I,2,FALSE) -> 800 | I29: =H29/J$5 -> 0.010976798
A30: Auto | B30: 1 | C30: 1 | E30: 11507 | F30: 2938 | G30: 0.04031229 | H30: =VLOOKUP(E30,Link_TAZ_lookup!H:I,2,FALSE) -> 2938 | I30: =H30/J$5 -> 0.04031229
A31: Auto | B31: 1 | C31: 1 | E31: 11506 | F31: 250 | G31: 0.0034302493 | H31: 250 | I31: =H31/J$5 -> 0.0034302493
A32: Auto | B32: 1 | C32: 1 | E32: 11505 | F32: 2150 | G32: 0.029500144 | H32: =VLOOKUP(E32,Link_TAZ_lookup!H:I,2,FALSE) -> 2150 | I32: =H32/J$5 -> 0.029500144
A33: Auto | B33: 1 | C33: 1 | D33: US 90 | E33: 11503 | F33: 3496 | G33: 0.047968606 | H33: =VLOOKUP(E33,Link_TAZ_lookup!H:I,2,FALSE) -> 3496 | I33: =H33/J$5 -> 0.047968606
A34: Auto | B34: 1 | C34: 1 | D34: US 98 | E34: 11502 | F34: 7388 | G34: 0.10137073 | H34: =VLOOKUP(E34,Link_TAZ_lookup!H:I,2,FALSE) -> 7388 | I34: =H34/J$5 -> 0.10137073
A35: Auto | B35: 1 | C35: 1 | D35: AL 182 | E35: 11501 | F35: 7500 | G35: 0.10290748 | H35: =VLOOKUP(E35,Link_TAZ_lookup!H:I,2,FALSE) -> 7500 | I35: =H35/J$5 -> 0.10290748
A36: Auto | B36: 2 | C36: 2 | E36: 11554 | F36: 400 | G36: 0.011376564 | H36: 400 | I36: =H36/J$36 -> 0.011376564 | J36: =SUM(H36:H56) -> 35160
A37: Auto | B37: 2 | C37: 2 | D37: US 441 | E37: 11553 | F37: 375 | G37: 0.010665529 | H37: =VLOOKUP(E37,Link_TAZ_lookup!H:I,2,FALSE) -> 375 | I37: =H37/J$36 -> 0.010665529
A38: Auto | B38: 2 | C38: 2 | E38: 11552 | F38: 632 | G38: 0.017974972 | H38: =VLOOKUP(E38,Link_TAZ_lookup!H:I,2,FALSE) -> 632 | I38: =H38/J$36 -> 0.017974972
A39: Auto | B39: 2 | C39: 2 | E39: 11551 | F39: 800 | G39: 0.022753129 | H39: =VLOOKUP(E39,Link_TAZ_lookup!H:I,2,FALSE) -> 800 | I39: =H39/J$36 -> 0.022753129
A40: Auto | B40: 2 | C40: 2 | D40: US 41 (split 1300) | E40: 11550 | F40: 1400 | G40: 0.039817975 | H40: 1400 | I40: =H40/J$36 -> 0.039817975
...

Sheet Link_TAZ_lookup
A1: LINK_ID | B1: COSITE | C1: FTI_23 | D1: COUNT_23 | E1: ExternalZone
A2: 100009 | B2: 290090 | C2: 375 | D2: 375 | E2: 11553 | H2: Row Labels | I2: Sum of COUNT_23
A3: 100010 | B3: 740156 | C3: 1750 | D3: 1750 | E3: 11557 | H3: 11501 | I3: 7500
A4: 135882 | B4: 500237 | C4: 500 | D4: 500 | E4: 11537 | H4: 11502 | I4: 7388
A5: 195041 | B5: 600131 | C5: 1450 | D5: 1450 | E5: 11515 | H5: 11503 | I5: 3496
A6: 202797 | B6: 520077 | C6: 850 | D6: 850 | E6: 11520 | H6: 11504 | I6: 36000
A7: 202812 | B7: 520187 | C7: 475 | D7: 475 | E7: 11521 | H7: 11505 | I7: 2150
A8: 204900 | B8: 359118 | C8: 225 | D8: 225 | E8: 11545 | H8: 11507 | I8: 2938
A9: 204990 | B9: 350092 | C9: 1900 | D9: 1900 | E9: 11547 | H9: 11508 | I9: 800
A10: 205297 | B10: 530247 | C10: 1476 | D10: 1476 | E10: 11527 | H10: 11509 | I10: 5750
A11: 205587 | B11: 520016 | C11: 2050 | D11: 2050 | E11: 11525 | H11: 11510 | I11: 575
A12: 207743 | B12: 570001 | C12: 2000 | D12: 2000 | E12: 11513 | H12: 11512 | I12: 2025
A13: 212772 | B13: 500306 | C13: 350 | D13: 350 | E13: 11535 | H13: 11513 | I13: 2000
A14: 212849 | B14: 500281 | C14: 678 | D14: 678 | E14: 11536 | H14: 11514 | I14: 2000
... A55: 260444 | B55: 480501 | C55: 2150 | D55: 2150 | E55: 11505 | H55: 11560 | I55: 75636
A56: 261258 | B56: 482001 | C56: 18000 | D56: 18000 | E56: 11504 | H56: (blank)
A57: 348182 | B57: 482001 | C57: 18000 | D57: 18000 | E57: 11504 | H57: Grand Total | I57: 275668
A58: 355262 | B58: 480048 | C58: 3496 | D58: 3496 | E58: 11503
A59: 196791 | B59: 480325 | C59: 7388 | D59: 7388 | E59: 11502
A60: 259683 | B60: 480461 | C60: 7500 | D60: 7500 | E60: 11501
A61: 191934 | B61: 550001 | C61: 175 | D61: 175 | E61: 11541
A62: 243988 | B62: 540002 | C62: 2250 | D62: 2250 | E62: 11542
A63: 243989 | B63: 540002 | C63: 2250 | D63: 2250 | E63: 11542
A64: 136153 | B64: 540222 | C64: 250 | D64: 250 | E64: 11543

Sheet Airport
A1: Market | B1: DMA | C1: NextGen_TAZ | D1: share
A2: Airport | B2: 1 | C2: 7656 | D2: 0.38116818
A3: Airport | B3: 1 | C3: 8237 | D3: 0.61883182
A4: Airport | B4: 2 | C4: 6429 | D4: 0.40133779
A5: Airport | B5: 2 | C5: 7812 | D5: 0.59866221
A6: Airport | B6: 3 | C6: 7536 | D6: 1
A7: Airport | B7: 4 | C7: 5757 | D7: 0.45268542
A8: Airport | B8: 4 | C8: 4302 | D8: 0.54731458
A9: Airport | B9: 5 | C9: 4657 | D9: 0.9465233
A10: Airport | B10: 5 | C10: 5529 | D10: 0.053476698
A11: Airport | B11: 6 | C11: 3279 | D11: 0.10531208
A12: Airport | B12: 6 | C12: 3673 | D12: 0.89468792
A13: Airport | B13: 7 | C13: 2315 | D13: 0.11556881
... A19: Airport | B19: 8 | C19: 2090 | D19: 0.074531118

Sheet CanaveralCruiseTrips
A1: NextGen_TAZ | B1: HotelRoom_Share
A2: 4611 | B2: 0.008602915
A3: 4615 | B3: 0.022076075
A4: 4616 | B4: 0.088730892
A5: 4625 | B5: 0.015748311
A6: 4629 | B6: 0.011695699
A7: 4633 | B7: 0.048346961
A8: 4641 | B8: 0.07440455
A9: 4642 | B9: 0.027337362
A10: 4643 | B10: 0.0057945254
A11: 4644 | B11: 0.026199787
A12: 4646 | B12: 0.12651973
A13: 4649 | B13: 0.0078208319
... A25: 4708 | B25: 0.038286527
